Workbook

Sheet Sheet1 (6)
A1: ADITYA BIRLA INTERMEDIATE COLLEGE RENUKOOT
A2: TIME OFFICE FEE DEDUCTION LIST FOR THE MONTHS OF APRIL-2026 TO SEP-2026 CLASS - 12 B MATHS DATE :- 04-09-2026
A3: S.NO. | B3: ROLL NO | C3: S.R. NO. | D3: STUDENT'S NAME | E3: FATHER'S NAME | F3: E.CODE | G3: DEPT. | H3: FEE AMNOUNT
A4: 1 | B4: 5 | C4: 37239 | D4: AKEEB AHMAD | E4: ZULPHIKAR AHMAD | F4: 026724 | G4: E xt PRESS | H4: 4435
A5: 2 | B5: 10 | C5: 39076 | D5: ASHUTOSH YADAV | E5: YOGENDRA YADVA | F5: 025781 | G5: POT ROOM | H5: 4435
A6: 3 | B6: 20 | C6: 37253 | D6: PUSHPRAJ SHARMA | E6: SHIV SHANKAR SHARMA | F6: 032481 | G6: ALU DIGN OPTR | H6: 4435
A7: 4 | B7: 27 | C7: 39007 | D7: SHASHIKANT TRIPATHI | E7: KAMLESH KUMAR TRIPATHI | F7: 022403 | G7: POT ROOM | H7: 4435
A8: 5 | B8: 30 | C8: 37181 | D8: SHIVAM CHAURASIA | E8: SUBHASH CHAURASIA | F8: 026052 | G8: POT ROOM | H8: 4435
A9: 6 | B9: 39 | C9: 38995 | D9: ANANYA YADAV | E9: DEVNARAYAN YADAV | F9: 026633 | G9: POTROOM | H9: 4435
A10: 7 | B10: 40 | C10: 37070 | D10: ANSHU SINGH | E10: JITENDRA SINGH | F10: 027269 | G10: POTROOM | H10: 4435
A11: 8 | B11: 41 | C11: 38990 | D11: ANUSHKA YADAV | E11: JAMAWANT SINGH YADAV | F11: 028486 | G11: POT ROOM | H11: 4435
A12: 9 | B12: 48 | C12: 38999 | D12: KUMKUM | E12: VIJAY RAY | F12: 024022 | G12: ALU INS | H12: 4435
A13: 10 | B13: 50 | C13: 37069 | D13: MIMANSHA | E13: SHAILENDRA KUMAR CHAUDHARY | F13: 024448 | G13: R/MILL OPTR | H13: 4435
A14: 11 | B14: 51 | C14: 37068 | D14: NISHA MISHRA | E14: MANOJ KUMAR MISHRA | F14: 029734 | G14: POT ROOM | H14: 4435
A15: 12 | B15: 55 | C15: 37143 | D15: SANJANA KUMARI RAI | E15: DINESH KUMAR RAI | F15: 026696 | G15: POTROOM | H15: 4435
A16: 13 | B16: 57 | C16: 37124 | D16: SHRUTI PANDEY | E16: SANJAY KUMAR PANDEY | F16: 031028 | G16: POTROOM | H16: 4435

Sheet Sheet1 (5)
A1: ROLL NO. | B1: class | C1: S.R. NO. | D1: roll numer 10th | E1: PEN NUMBER | F1: AADHAR NO. | G1: D.O.B. | H1: DD | I1: MM | J1: YYYY | K1: STUDENT'S NAME | L1: STUDENT NAME IN HINDI | M1: FATHER'S NAME | N1: FATHER'S NAME IN HINDI | O1: MOTHER'S NAME | P1: MOTHER'S NAME IN HINDI | Q1: GENDER | S1: CASTE | T1: CAT. | V1: RELIGION | X1: ADDRESS | Y1: MOB. NO. | Z1: EMAIL ID | AA1: OCCUPATION Other-OTH / Hindalco -HE / Hindalco Supply- HS | AB1: E.CODE | AC1: DEPT.
A2: 1 | B2: 12B | C2: 38954 | D2: 1252255509 | E2: 21135989316 | F2: 270538963986 | G2: 39771 | H2: 19 | I2: 11 | J2: 2008 | K2: ABHIMANYU YADAV | L2: अभिमन्यु यादव | M2: SRILAL YADAV | N2: श्रीलाल यादव | O2: SONA DEVI | P2: सोना देवी | Q2: M | R2: 1 | S2: AHIR | T2: OBC | U2: 3 | V2: H | W2: 0 | X2: RAM NARAYAN KATRA RENUKOOT | Y2: 9598799195 | Z2: SONARKT1980@GMAIL.COM | AA2: OTH
A3: 2 | B3: 12B | C3: 40126 | D3: 1252263773 | E3: 22837855275 | F3: 4403-7464-2243 | G3: 40121 | H3: 4 | I3: 11 | J3: 2009 | K3: ABHISHEK GUPTA | L3: अभिषेक गुप्ता | M3: AYODHYA PRASAD | N3: अयोध्या प्रसाद | O3: SAPANA GUPTA | P3: सपना गुप्ता | Q3: M | R3: 1 | S3: RONIAR | T3: OBC | U3: 3 | V3: H | W3: 0 | X3: BAINA SAGOBANDH | Y3: 8756958156 | Z3: abhishekgupta24371626@gmail.com | AA3: OTH
A4: 3 | B4: 12B | C4: 40127 | D4: 1252263775 | E4: 22694052014 | F4: 4826-2982-3472 | G4: 39814 | H4: 01 | I4: 01 | J4: 2009 | K4: ABHISHEK KUMAR | L4: अभिषेक कुमार | M4: DINESH KUMAR | N4: दिनेश कुमार | O4: GEETA DEVI | P4: गीता देवी | Q4: M | R4: 1 | S4: RONIAR | T4: OBC | U4: 3 | V4: H | W4: 0 | X4: BAINA SAGOBANDH | Y4: 9198889355 | Z4: abhishekkumar8989@gmail.com | AA4: OTH
A5: 4 | B5: 12B | C5: 37212 | D5: 1252255528 | E5: 21308620363 | F5: 9392-9598-5025 | G5: 39868 | H5: 24 | I5: 02 | J5: 2009 | K5: AJIT KUMAR | L5: अजीत कुमार | M5: MANOJ RAM | N5: मनोज राम | O5: SHEELA DEVI | P5: शीला देवी | Q5: M | R5: 1 | S5: HARIJAN | T5: SC | U5: 1 | V5: H | W5: 0 | X5: H1/35 ABCIL RENUKOOT | Y5: 9140875958 | Z5: AJITKUMAR93RKT@GMAIL.COM | AA5: OTH
A6: 5 | B6: 12B | C6: 37239 | D6: 1252255535 | E6: 21326918699 | F6: 4253-7939-5883 | G6: 39939 | H6: 06 | I6: 05 | J6: 2009 | K6: AKEEB AHMAD | L6: अकीब अहमद | M6: ZULPHIKAR AHMAD | N6: जुल्फिकार अहमद | O6: NAGMA BEGAM | P6: नगमा बेगम | Q6: M | R6: 1 | S6: ISLAM | T6: GEN | U6: 4 | V6: M | W6: 1 | X6: L-1072 HINDALCO COLONY RENUKOOT | Y6: 7985412595 | Z6: AAKEEBAHMAD4@GMAIL.COM | AA6: HE | AB6: 026724 | AC6: E xt PRESS
A7: 6 | B7: 12B | C7: 39030 | D7: 1252255545 | E7: 21092525382 | F7: 389857903391 | G7: 39950 | H7: 17 | I7: 05 | J7: 2009 | K7: ANKIT KUMAR SHARMA | L7: अंकित कुमार शर्मा | M7: ARVIND KUMAR SHARMA | N7: अरविन्द कुमार शर्मा | O7: GUNJA DEVI | P7: गुन्जा देवी | Q7: M | R7: 1 | S7: LOHAR | T7: OBC | U7: 3 | V7: H | W7: 0 | X7: HOUSE NUMBER 340 WARD NUMBER 16 SABJI MANDI RENUKUT | Y7: 9598422808 | Z7: ANKIT09RKT@GMAIL.COM | AA7: OTH
A8: 7 | B8: 12B | C8: 39056 | D8: 1252255548 | E8: 21573201849 | F8: 940879560324 | G8: 40544 | H8: 01 | I8: 01 | J8: 2011 | K8: ANMOL KUMAR | L8: अनमोल कुमार | M8: SHIV POOJAN | N8: शिव पुजन | O8: DEV LATA DEVI | P8: देवलता देवी | Q8: M | R8: 1 | S8: RONIYAR | T8: OBC | U8: 3 | V8: H | W8: 0 | X8: VISHWAKARMA NAGAR RENUKOOT | Y8: 9519725292 | Z8: AWANITK94@GMAIL.COM | AA8: OTH
A9: 8 | B9: 12B | C9: 40121 | D9: 1252267352 | E9: 21327890764 | F9: 6126-4507-0552 | G9: 39448 | H9: 01 | I9: 01 | J9: 2008 | K9: ANSHUL KUMAR | L9: अंशुल कुमार | M9: NANDLAL | N9: नन्दलाल | O9: NINTA DEVI | P9: निनता देवी | Q9: M | R9: 1 | S9: KUMHAR | T9: OBC | U9: 3 | V9: H | W9: 0 | X9: KACHAN KIRBILA MAIYURPUR SONBHADRA | Y9: 8400510565 | Z9: anshulkum565@gmail.com | AA9: OTH
A10: 9 | B10: 12B | C10: 39032 | D10: 1252255554 | E10: 22786885814 | F10: 387090609033 | G10: 39649 | H10: 20 | I10: 07 | J10: 2008 | K10: ANURAG GUPTA | L10: अनुराग गुप्ता | M10: BANARSI PRASAD | N10: बनारसी प्रसाद | O10: RAMAVTI | P10: रमावती | Q10: M | R10: 1 | S10: KANDU | T10: OBC | U10: 3 | V10: H | W10: 0 | X10: IN FRONT OF C226 HUT, TURRA, PIPRI, | Y10: 8090498955 | Z10: BANARASIPRASAD00@GMAIL.COM | AA10: SUPPLY
A11: 10 | B11: 12B | C11: 39076 | D11: 1252255566 | E11: 21052522520 | F11: 5483-1530-4549 | G11: 40544 | H11: 01 | I11: 01 | J11: 2011 | K11: ASHUTOSH YADAV | L11: आशुतोष यादव | M11: YOGENDRA YADVA | N11: योगेन्द्र यादव | O11: GEETA DEVI | P11: गीता देवी | Q11: M | R11: 1 | S11: AHIR | T11: OBC | U11: 3 | V11: H | W11: 0 | X11: I-1731 HINDALCO COLONY RENUKOOT SONEBHADRA | Y11: 8858353002 | Z11: YADAVKIRAN0435@GMAIL.COM | AA11: HE | AB11: 025781 | AC11: POT ROOM
A12: 11 | B12: 12B | C12: 39096 | D12: 1252255569 | E12: 21499203466 | F12: 2270-9714-1598 | G12: 40035 | H12: 10 | I12: 08 | J12: 2009 | K12: AWDHESH KUMAR | L12: अवधेश कुमार | M12: DEVDUTT YADAV | N12: देवदत्त यादव | O12: KIRAN DEVI | P12: किरन देवी | Q12: M | R12: 1 | S12: AHIR | T12: OBC | U12: 3 | V12: H | W12: 0 | X12: I 708 HINDALCO COLONY RENUKOOT | Y12: 9695268145 | Z12: SUDESHWAR.PRASAD@GMAIL.COM | AA12: OTH
A13: 12 | B13: 12B | C13: 37170 | D13: 1252255575 | E13: 21245074882 | F13: 572604048622 | G13: 39517 | H13: 10 | I13: 03 | J13: 2008 | K13: AYUSH KUMAR | L13: आयुष कुमार | M13: PAPPU KUMAR MEHTA | N13: पप्पू कुमार मेहता | O13: MALA DEVI | P13: माला देवी | Q13: M | R13: 1 | S13: KOIRY | T13: OBC | U13: 3 | V13: H | W13: 0 | X13: VISHWAKARMA NAGAR RENUKOOT | Y13: 7398694084 | Z13: MEHTAPAPPUKUMAR7400@GMAIL.COM | AA13: SUPPLY
A14: 13 | B14: 12B | C14: 37217 | D14: 1252255571 | E14: 21499651012 | F14: 2915-1341-6139 | G14: 39998 | H14: 04 | I14: 07 | J14: 2009 | K14: AYUSH KUMAR | L14: आयुष कुमार | M14: PARMESHWAR KUMAR | N14: परमेश्वर कुमार | O14: SARITA SAH | P14: सरिता साह | Q14: M | R14: 1 | S14: GOND | T14: ST | U14: 2 | V14: H | W14: 0 | X14: BACK ON M TYPE HOUSE | Y14: 8953295243 | Z14: SHASHCHINI171@GMAIL.COM | AA14: OTH
A15: 14 | B15: 12B | C15: 40147 | D15: 1252269491 | E15: 21422879109 | F15: 386281120721 | G15: 40544 | H15: 01 | I15: 01 | J15: 2011 | K15: CHANDAN KUMAR | L15: चंदन कुमार | M15: DEV KUMAR | N15: देव कुमार | O15: KAUSHILYA | P15: कौशल्या | Q15: M | R15: 1 | S15: AHIR | T15: OBC | U15: 3 | V15: H | W15: 0 | X15: T-231 HINDALCO COLONY RENUKOOT | Y15: 9651486966 | Z15: MY2766926@GMAIL.COM | AA15: OTH
A16: 15 | B16: 12B | C16: 37180 | D16: 1252255584 | E16: 21294843958 | F16: 927197697060 | G16: 40138 | H16: 21 | I16: 11 | J16: 2009 | K16: DEEPAK YADAV | L16: दीपक यादव | M16: KRISHNA YADAV | N16: कृष्णा यादव | O16: MAMTA DEVI | P16: ममता देवी | Q16: M | R16: 1 | S16: AHIR | T16: OBC | U16: 3 | V16: H | W16: 0 | X16: NEAR V-MART PATEL BHAWAN RENUKOOT | Y16: 9936431332 | Z16: DEEPAKWATOLA2009@GMAIL.COM | AA16: OTH
A17: 16 | B17: 12B | C17: 39062 | D17: 1252255589 | E17: 23010833902 | F17: 521226798038 | G17: 39752 | H17: 31 | I17: 10 | J17: 2008 | K17: GIRDHAR GOPAL | L17: गिरधर गोपाल | M17: DINESH KUMAR | N17: दिनेश कुमार | O17: PUSHPA DEVI | P17: पुष्पा देवी | Q17: M | R17: 1 | S17: RAUNIYAR | T17: OBC | U17: 3 | V17: H | W17: 0 | X17: SAGOBANDH BABHANI | Y17: 7054291240 | Z17: GIRIDHARGOPAL7054@GMAIL.COM | AA17: OTH
A18: 17 | B18: 12B | C18: 39020 | D18: 1252255607 | E18: 21065800616 | F18: 6615-4139-5409 | G18: 40014 | H18: 20 | I18: 07 | J18: 2009 | K18: KRISHNA KUMAR | L18: कृष्णा कुमार | M18: DAYANAND | N18: दयानन्द | O18: JAYATRI DEVI | P18: जयत्री देवी | Q18: M | R18: 1 | S18: AHIR | T18: OBC | U18: 3 | V18: H | W18: 0 | X18: VISHWAKARMA NAGAR RENUKOOT | Y18: 8081749763 | Z18: KRISHNABABU2072009@GMAIL.COM | AA18: OTH
A19: 18 | B19: 12B | C19: 39070 | D19: 1252255610 | E19: 21296027832 | F19: 671190469526 | G19: 40534 | H19: 22 | I19: 12 | J19: 2010 | K19: KUNAL PRATAP SINGH | L19: कुनाल प्रताप सिंह | M19: RAVINDRA KUMAR SINGH | N19: रविन्द्र कुमार सिंह | O19: UMA SINGH | P19: उमा सिंह | Q19: M | R19: 1 | S19: KSHATIRIYA | T19: GEN | U19: 4 | V19: H | W19: 0 | X19: KHADH PATHAR MURDHWAH | Y19: 9452636920 | Z19: RAVISINGH82777@GMAIL.COM | AA19: OTH
A20: 19 | B20: 12B | C20: 37224 | D20: 1252255621 | E20: 21325384557 | F20: 3021-6033-0557 | G20: 39949 | H20: 16 | I20: 05 | J20: 2009 | K20: MO. HASIM | L20: मो. हासिम | M20: AFTAB AHMAD | N20: आफताब अहमद | O20: SHAHAJAHAN PARVEEN | P20: शाहजहाँ परवीन | Q20: M | R20: 1 | S20: ISLAM | T20: GEN | U20: 4 | V20: M | W20: 1 | X20: VISHWAKARMA NAGAR | Y20: 8853120790 | Z20: KHANHASHIM93451@GMAIL.COM | AA20: OTH
A21: 20 | B21: 12B | C21: 37253 | D21: 1252255649 | E21: 21754387620 | F21: 537850185546 | G21: 39594 | H21: 26 | I21: 05 | J21: 2008 | K21: PUSHPRAJ SHARMA | L21: पुष्पराज शर्मा | M21: SHIV SHANKAR SHARMA | N21: शिव शंकर शर्मा | O21: SUNITA SHARMA | P21: सुनीता शर्मा | Q21: M | R21: 1 | S21: NAI | T21: OBC | U21: 3 | V21: H | W21: 0 | X21: T-1168 HINDALCO COLONY RENUKOOT | Y21: 9125374243 | Z21: SHARMAPUSPRAJ221@GMAIL.COM | AA21: HE | AB21: 032481 | AC21: ALU DIGN OPTR
A22: 21 | B22: 12B | C22: 38924 | D22: 1252255650 | E22: 21064854622 | F22: 547719947971 | G22: 39545 | H22: 07 | I22: 04 | J22: 2008 | K22: RAHUL KUMAR SINGH | L22: राहुल कुमार सिंह | M22: RAJESH KUMAR SINGH | N22: राजेश कुमार सिंह | O22: MAYA DEVI | P22: माया देवी | Q22: M | R22: 1 | S22: KAHAR | T22: OBC | U22: 3 | V22: H | W22: 0 | X22: GRASIM INDUSTRY LIMITED,RENUKOOT | Y22: 9918420798 | Z22: RAJESHKUMARSINGH141983@GMAIL.COM | AA22: OTH
A23: 22 | B23: 12B | C23: 40139 | D23: 1252266436 | E23: 21184653009 | F23: 4816-6395-9975 | G23: 39814 | H23: 01 | I23: 01 | J23: 2009 | K23: ROHIT | L23: रोहित | M23: HARE RAM BIND | N23: हरे राम बिंद | O23: CHINTA DEVI | P23: चिंता देवी | Q23: M | R23: 1 | S23: BIND | T23: OBC | U23: 3 | V23: H | W23: 0 | X23: NEAR CHARCH HI-TECH MURDHAWA | Y23: 7347759011 | Z23: ROHITKUMARRKT7347@GMAIL.COM | AA23: OTH
A24: 23 | B24: 12B | C24: 39033 | D24: 1252255658 | E24: 21122055237 | F24: 375327782079 | G24: 39686 | H24: 26 | I24: 08 | J24: 2008 | K24: ROHIT YADAV | L24: रोहित यादव | M24: MUNIB YADAV | N24: मुनीब यादव | O24: SINDHU DEVI | P24: सिन्धू देवी | Q24: M | R24: 1 | S24: AHIR | T24: OBC | U24: 3 | V24: H | W24: 0 | X24: WARD NO. -08 CHACHA COLONY RENUKOOT | Y24: 9026392776 | Z24: MR.RY.ROHIT.YADAV@GMAIL.COM | AA24: SUPPLY
A25: 24 | B25: 12B | C25: 37228 | D25: 1252255661 | E25: 21607635206 | F25: 6980-5025-8006 | G25: 39780 | H25: 28 | I25: 11 | J25: 2008 | K25: RUDRAKSH SINGH | L25: रुद्राक्ष सिंह | M25: SHIV VIJAY SINGH | N25: शिव विजय सिंह | O25: USHA SINGH | P25: उषा सिंह | Q25: M | R25: 1 | S25: KSHATRIYA | T25: GEN | U25: 4 | V25: H | W25: 0 | X25: WARD -11 CHACHA COL | Y25: 7275130076 | Z25: SINGHSHIVVIJAY75@GMAIL.COM | AA25: OTH
A26: 25 | B26: 12B | C26: 37281 | D26: 1252255666 | E26: 21416650253 | F26: 7429-2349-3729 | G26: 40341 | H26: 12 | I26: 06 | J26: 2010 | K26: SATISH KUMAR CHAURASIYA | L26: सतीश कुमार चौरसिया | M26: SANTOSH KUMAR CHAURASIYA | N26: सन्तोष कुमार चौरसिया | O26: REETA CHAURASIYA | P26: रीता चौरसिया | Q26: M | R26: 1 | S26: BARAI | T26: OBC | U26: 3 | V26: H | W26: 0 | X26: VISHWAKARMA NAGAR | Y26: 7052466964 | Z26: SNTOSHCHAURASIYA8@GMAIL.COM | AA26: OTH
A27: 26 | B27: 12B | C27: 37232 | D27: 1252255670 | E27: 21373952980 | F27: 8837-6094-3979 | G27: 40439 | H27: 18 | I27: 09 | J27: 2010 | K27: SATYANAND YADAV | L27: सत्यानन्द यादव | M27: JAGDISH YADAV | N27: जगदीश यादव | O27: SANJU DEVI | P27: संजू देवी | Q27: M | R27: 1 | S27: AHIR | T27: OBC | U27: 3 | V27: H | W27: 0 | X27: NEAR V-MART | Y27: 9936431332 | Z27: SATYANANDYADAV2010@GMAIL.COM | AA27: OTH
A28: 27 | B28: 12B | C28: 39007 | D28: 1252255676 | E28: 21103030347 | F28: 326247983646 | G28: 39704 | H28: 13 | I28: 09 | J28: 2008 | K28: SHASHIKANT TRIPATHI | L28: शशिकान्त त्रिपाठी | M28: KAMLESH KUMAR TRIPATHI | N28: कमलेश कुमार त्रिपाठी | O28: RINKI DEVI | P28: रिंकी देवी | Q28: M | R28: 1 | S28: BRAHMIN | T28: GEN | U28: 4 | V28: H | W28: 0 | X28: I522 HINDALCO COLONY RENUKOOT | Y28: 9452863359 | Z28: KAMLESHKUMARTRIPATHI31@GMAIL.COM | AA28: HE | AB28: 022403 | AC28: POT ROOM
A29: 28 | B29: 12B | C29: 37260 | D29: 1252255679 | E29: 21251968693 | F29: 702091095930 | G29: 39792 | H29: 10 | I29: 12 | J29: 2008 | K29: SHIV SAGAR YADAV | L29: शिव सागर यादव | M29: SANT RAJ YADAV | N29: संत राज यादव | O29: LALITA DEVI | P29: ललिता देवी | Q29: M | R29: 1 | S29: AHIR | T29: OBC | U29: 3 | V29: H | W29: 0 | X29: WARD NO.-01 RAILWAY COLONY, TURRA RENUKOOT | Y29: 9918881937 | Z29: SY1721626@GMAIL.COM | AA29: OTH
A30: 29 | B30: 12B | C30: 37242 | D30: 1252255681 | E30: 21630284194 | F30: 551668261476 | G30: 39996 | H30: 02 | I30: 07 | J30: 2009 | K30: SHIVAM | L30: शिवम | M30: UDAY RAM | N30: उदय राम | O30: SANGITA DEVI | P30: संगीता देवी | Q30: M | R30: 1 | S30: HARIJAN | T30: SC | U30: 1 | V30: H | W30: 0 | X30: WARD NO. -09 JHARNA BASTI RENUKOOT | Y30: 9519722384 | Z30: SANGITASANGITA77546@GMAIL.COM | AA30: SUPPLY
A31: 30 | B31: 12B | C31: 37181 | D31: 1252255682 | E31: 21429175519 | F31: 339463992456 | G31: 39912 | H31: 09 | I31: 04 | J31: 2009 | K31: SHIVAM CHAURASIA | L31: शिवम चौरसिया | M31: SUBHASH CHAURASIA | N31: सुभाष चौरसिया | O31: SUNITA CHAURASIYA | P31: सुनीता चौरसिया | Q31: M | R31: 1 | S31: BARAI | T31: OBC | U31: 3 | V31: H | W31: 0 | X31: HH-254 HINDALCO COLONY RENUKOOT | Y31: 8858125721 | Z31: SHUBHASHCHARKT@GMAIL.COM | AA31: HE | AB31: 026052 | AC31: POT ROOM
A32: 31 | B32: 12B | C32: 37746 | D32: 1252255689 | E32: 21504052054 | F32: 3193-1376-6740 | G32: 40223 | H32: 14 | I32: 02 | J32: 2010 | K32: SHIVAM MISHRA | L32: शिवम मिश्र | M32: GYAN PRAKASH MISHRA | N32: ज्ञान प्रकाश मिश्र | O32: MANJU DEVI | P32: मंजू देवी | Q32: M | R32: 1 | S32: BRAHMIN | T32: GEN | U32: 4 | V32: H | W32: 0 | X32: CHACHA COLONY RENUKOOT | Y32: 9125091601 | Z32: SKM498174@GMAIL.COM | AA32: OTH
A33: 32 | B33: 12B | C33: 39029 | D33: 1252255701 | E33: 21264654264 | F33: 800328553493 | G33: 39886 | H33: 14 | I33: 03 | J33: 2009 | K33: SURAJ YADAV | L33: सूरज यादव | M33: RAMKER YADAV | N33: रामकेर यादव | O33: KAUSHALYA DEVI | P33: कौशल्या देवी | Q33: M | R33: 1 | S33: AHIR | T33: OBC | U33: 3 | V33: H | W33: 0 | X33: SHIVA PARK RENUKOOT | Y33: 9305949533 | Z33: UMESHYADAV5277@GMAIL.COM | AA33: OTH
A34: 33 | B34: 12B | C34: 37160 | D34: 1252255708 | E34: 21325838055 | F34: 699215999117 | G34: 40130 | H34: 13 | I34: 11 | J34: 2009 | K34: VANSH MITTAL | L34: वंश मित्तल | M34: RAJU MITTAL | N34: राजू मित्तल | O34: NEELAM MITTAL | P34: नीलम मित्तल | Q34: M | R34: 1 | S34: BANIYA | T34: GEN | U34: 4 | V34: H | W34: 0 | X34: IN FRONT OF PNB SHIVAPARK | Y34: 7398773797 | Z34: RAJUAGRAWAL37850@GMAIL.COM | AA34: OTH
A35: 34 | B35: 12B | C35: 38272 | D35: 1252255715 | E35: 21370961997 | F35: 732100554113 | G35: 40225 | H35: 16 | I35: 02 | J35: 2010 | K35: VISHAL SINGH | L35: विशाल सिंह | M35: JAY PRAKASH SINGH | N35: जय प्रकाश सिंह | O35: BHAGMANI DEVI | P35: भागमनी देवी | Q35: M | R35: 1 | S35: KURMI | T35: OBC | U35: 3 | V35: H | W35: 0 | X35: ABCIL HOSTEL RENUKOOT | Y35: 9721686499 | Z35: POOJA277504@GMAIL.COM | AA35: OTH
A36: 35 | B36: 12B | C36: 40107 | D36: 1252263857 | E36: 22650034990 | F36: 4243-3106-7988 | G36: 39938 | H36: 05 | I36: 05 | J36: 2009 | K36: VISHNU KANT | L36: विष्णु कांत | M36: SANJAY KUMAR | N36: संजय कुमार | O36: LALTI DEVI | P36: लालती देवी | Q36: M | R36: 1 | S36: RONIAR | T36: OBC | U36: 3 | V36: H | W36: 0 | X36: BAINA SAGOBANDH | Y36: 6386345720 | Z36: vishnu752398@gmail.com | AA36: OTH
A37: 36 | B37: 12B | C37: 36488 | D37: 1242447193 | E37: 21600449694 | F37: 7167-3905-0861 | G37: 39840 | H37: 27 | I37: 01 | J37: 2009 | K37: VIVEK KUMAR SINGH | L37: विवेक कुमार सिंह | M37: VINOD KUMAR | N37: विनोद कुमार | O37: CHANDA DEVI | P37: चंदा देवी | Q37: M | R37: 1 | S37: KOIRI | T37: OBC | U37: 3 | V37: H | W37: 0 | X37: WARD NUMBER 03 RENUKOOT | Y37: 7522057072 | Z37: vkmaurya1985up@gmail.com | AA37: OTH
A38: 37 | B38: 12B | C38: 37156 | D38: 1252255728 | E38: 21610671260 | F38: 912374096360 | G38: 39940 | H38: 07 | I38: 05 | J38: 2009 | K38: AKRITI | L38: कुमारी आकृति | M38: RAM AUTAR | N38: राम औतार | O38: URMILA DEVI | P38: उर्मिला देवी | Q38: F | R38: 2 | S38: KALAR | T38: OBC | U38: 3 | V38: H | W38: 0 | X38: NEAR V MART PRIMARY SCHOOL RENUKOOT | Y38: 8853767194 | Z38: AKRITISHISHTOLA2009@GMAIL.COM | AA38: OTH
A39: 38 | B39: 12B | C39: 38940 | D39: 1252255736 | E39: 21473874271 | F39: 982931653622 | G39: 40143 | H39: 26 | I39: 11 | J39: 2009 | K39: ANANDI KUMARI SINGH | L39: आनन्दी कुमारी सिंह | M39: SHRIRAM SINGH | N39: श्रीराम सिंह | O39: LALITA DEVI | P39: ललिता देवी | Q39: F | R39: 2 | S39: AHIR | T39: OBC | U39: 3 | V39: H | W39: 0 | X39: JHOPADI NEAR BUS STAND | Y39: 9450320524 | Z39: VANDANASINGH8081961214@GMAIL.COM | AA39: OTH
A40: 39 | B40: 12B | C40: 38995 | D40: 1252255738 | E40: 21049747689 | F40: 926775823431 | G40: 39978 | H40: 14 | I40: 06 | J40: 2009 | K40: ANANYA YADAV | L40: अनन्या यादव | M40: DEVNARAYAN YADAV | N40: देवनारायण यादव | O40: VIMLA DEVI | P40: विमला देवी | Q40: F | R40: 2 | S40: AHIR | T40: OBC | U40: 3 | V40: H | W40: 0 | X40: SHIVA PARK RENUKOOT | Y40: 6394318895 | Z40: DAYADAV4303@GMAIL.COM | AA40: HE | AB40: 026633 | AC40: POTROOM
...

Sheet Sheet3
B2: चार्ट/डिस्प्ले | C2: विद्यार्थी
B3: 1. कक्षा में क्या करें (Do's in the Classroom) | C3: ABHIMANYU YADAV, ABHISHEK GUPTA, ABHISHEK KUMAR, AJIT KUMAR
B4: 2. कक्षा में क्या न करें (Don'ts in the Classroom) | C4: AKEEB AHMAD, ANKIT KUMAR SHARMA, ANMOL KUMAR, ANSHUL KUMAR
B5: 3. सुरक्षा नियम | C5: ANURAG GUPTA, ASHUTOSH YADAV, AWDHESH KUMAR, AYUSH KUMAR
B6: 4. यातायात नियम एवं सड़क सुरक्षा | C6: AYUSH KUMAR, CHANDAN KUMAR, DEEPAK YADAV
B7: 5. पोषण एवं संतुलित आहार | C7: GIRDHAR GOPAL, KRISHNA KUMAR, KUNAL PRATAP SINGH
B8: 6. साइबर सुरक्षा | C8: MO. HASIM, PUSHPRAJ SHARMA, RAHUL KUMAR SINGH
B9: 7. करियर जागरूकता | C9: ROHIT, ROHIT YADAV, RUDRAKSH SINGH
B10: 8. जन्मदिन कोना (Birthday Corner) | C10: SATISH KUMAR CHAURASIYA, SATYANAND YADAV, SHASHIKANT TRIPATHI
B11: 9. आज का विचार (Thought of the Day) | C11: SHIV SAGAR YADAV, SHIVAM, SHIVAM CHAURASIA
B12: 10. मूल्य चार्ट (Passion, Commitment, Integrity & Seamlessness) | C12: SHIVAM MISHRA, SURAJ YADAV, VANSH MITTAL
B13: 11. अंग्रेजी विषय चार्ट | C13: VISHAL SINGH, VISHNU KANT, VIVEK KUMAR SINGH
... B22: 20. विद्यार्थी उपलब्धि कोना (Student Achievement Corner) | C22: SWATI YADAV, TAJMIN BANO, UMRA

Sheet Sheet4
B4: क्र. | C4: चार्ट/डिस्प्ले | D4: विद्यार्थियों के नाम
B5: 1 | C5: कक्षा में क्या करें (Do's in the Classroom) | D5: AKRITI, ANANDI KUMARI SINGH
B6: 2 | C6: कक्षा में क्या न करें (Don'ts in the Classroom)
B7: 3 | C7: सुरक्षा नियम | D7: AKEEB AHMAD, ANKIT KUMAR SHARMA, ANANYA YADAV
B8: 4 | C8: यातायात नियम एवं सड़क सुरक्षा | D8: ANMOL KUMAR, ANSHUL KUMAR, ANSHU SINGH
B9: 5 | C9: पोषण एवं संतुलित आहार | D9: ANURAG GUPTA, ASHUTOSH YADAV, ANUSHKA YADAV
B10: 6 | C10: साइबर सुरक्षा | D10: AWDHESH KUMAR, AYUSH KUMAR, ASTHA SINGH
B11: 7 | C11: करियर जागरूकता | D11: AYUSH KUMAR, CHANDAN KUMAR, CHANCHAL
B12: 8 | C12: जन्मदिन कोना (Birthday Corner) | D12: DEEPAK YADAV, GIRDHAR GOPAL, ISHIKA KUMARI
B13: 9 | C13: आज का विचार (Thought of the Day) | D13: KRISHNA KUMAR, KUNAL PRATAP SINGH, JIVAN JYOTI KUMARI
B14: 10 | C14: मूल्य चार्ट (Passion, Commitment, Integrity & Seamlessness) | D14: MO. HASIM, PUSHPRAJ SHARMA, KHUSHI
B15: 11 | C15: अंग्रेजी विषय चार्ट | D15: RAHUL KUMAR SINGH, ROHIT, KHUSHI SINGH
B16: 12 | C16: हिन्दी विषय चार्ट | D16: ROHIT YADAV, RUDRAKSH SINGH, KUMKUM
B17: 13 | C17: गणित विषय चार्ट | D17: SATISH KUMAR CHAURASIYA, SATYANAND YADAV, MARIYAM NOOR
B18: 14 | C18: विज्ञान विषय चार्ट | D18: SHASHIKANT TRIPATHI, SHIV SAGAR YADAV, MIMANSHA
... B24: 20 | C24: विद्यार्थी उपलब्धि कोना (Student Achievement Corner) | D24: SWATI YADAV, TAJMIN BANO, UMRA, VISHAL SINGH

Sheet Sheet2
B1: ROLL NO. | C1: 7
B2: STUDENT'S NAME | C2: =VLOOKUP($C$1,'Sheet1 (5)'!A1:Z64,11,0) -> ANMOL KUMAR | E2: HE / SUPPLY / OTH | F2: =VLOOKUP($C$1,'Sheet1 (5)'!A1:AC69,27,0) -> OTH
B3: SR NO | C3: =VLOOKUP($C$1,'Sheet1 (5)'!A1:Z64,3,0) -> 39056 | E3: E.CODE | F3: =VLOOKUP($C$1,'Sheet1 (5)'!A1:AC69,28,0) -> 0
B4: FATHER'S NAME | C4: =VLOOKUP($C$1,'Sheet1 (5)'!A1:Z64,13,0) -> SHIV POOJAN | E4: DEPT | F4: =VLOOKUP($C$1,'Sheet1 (5)'!A2:AC69,29,0) -> 0
B5: MOTHER'S NAME | C5: =VLOOKUP($C$1,'Sheet1 (5)'!A1:Z66,15,0) -> DEV LATA DEVI
B6: D.O.B. | C6: =VLOOKUP($C$1,'Sheet1 (5)'!A1:Z68,7,0) -> 40544 | F6: CAT | G6: #M / F | H6: #M / F
F7: GEN | G7: M | H7: F
B8: ADDRESS | C8: =VLOOKUP($C$1,'Sheet1 (5)'!A1:Z69,24,0) -> VISHWAKARMA NAGAR RENUKOOT | G8: =COUNTIFS('Sheet1 (5)'!Q2:Q64,G7,'Sheet1 (5)'!T2:T64,F7) -> 7 | H8: =COUNTIFS('Sheet1 (5)'!Q2:Q64,H7,'Sheet1 (5)'!T2:T64,F7) -> 6 | I8: =SUM(G8:H8) -> 13 | P8: 13
B9: MOB. NO. | C9: =VLOOKUP($C$1,'Sheet1 (5)'!A1:Z69,25,0) -> 9519725292 | P9: 46
B10: EMAIL ID | C10: =LOWER(VLOOKUP($C$1,'Sheet1 (5)'!A1:Z69,26,0)) -> awanitk94@gmail.com | F10: HE/SUPPY/OTH | G10: #M / F | H10: #M / F | P10: 3
F11: SUPPLY | G11: M | H11: F | P11: 1
B12: PEN NUMBER | C12: =VLOOKUP($C$1,'Sheet1 (5)'!A1:Z69,5,0) -> 21573201849 | G12: =COUNTIFS('Sheet1 (5)'!Q2:Q64,G11,'Sheet1 (5)'!AA2:AA64,F11) -> 4 | H12: =COUNTIFS('Sheet1 (5)'!Q2:Q64,H11,'Sheet1 (5)'!AA2:AA64,F11) -> 4 | I12: =SUM(G12:H12) -> 8 | P12: =SUM(P8:P11) -> 63
B13: AADHAR NO. | C13: =VLOOKUP($C$1,'Sheet1 (5)'!A1:Z69,6,0) -> 940879560324
B15: Category | C15: =VLOOKUP($C$1,'Sheet1 (5)'!A1:Z69,20,0) -> OBC | F15: HINDU / MUSLIM | G15: #M / F | H15: #M / F
B16: Caste | C16: =VLOOKUP($C$1,'Sheet1 (5)'!A1:Z69,19,0) -> RONIYAR | F16: H | G16: M | H16: F
B17: Gender | C17: =VLOOKUP($C$1,'Sheet1 (5)'!A1:Z69,17,0) -> M | G17: =COUNTIFS('Sheet1 (5)'!Q2:Q64,G16,'Sheet1 (5)'!V2:V64,F16) -> 34 | H17: =COUNTIFS('Sheet1 (5)'!Q2:Q64,H16,'Sheet1 (5)'!V2:V64,F16) -> 22 | I17: =SUM(G17:H17) -> 56
B18: RELIGION | C18: =VLOOKUP($C$1,'Sheet1 (5)'!A1:Z69,22,0) -> H

Sheet Sheet1
A1: ADITYA BIRLA INTERMEDIATE COLLEGE RENUKOOT
A2: Employee / Supply Ward Details
A3: Sl. No. | B3: Admission No. | C3: Student Name | D3: Ward
A4: 1 | B4: 37239 | C4: AKEEB AHMAD | D4: Employee
A5: 2 | B5: 39076 | C5: ASHUTOSH YADAV | D5: Employee
A6: 3 | B6: 37253 | C6: PUSHPRAJ SHARMA | D6: Employee
A7: 4 | B7: 39007 | C7: SHASHIKANT TRIPATHI | D7: Employee
A8: 5 | B8: 37181 | C8: SHIVAM CHAURASIA | D8: Employee
A9: 6 | B9: 38995 | C9: ANANYA YADAV | D9: Employee
A10: 7 | B10: 37070 | C10: ANSHU SINGH | D10: Employee
A11: 8 | B11: 38990 | C11: ANUSHKA YADAV | D11: Employee
A12: 9 | B12: 38999 | C12: KUMKUM | D12: Employee
A13: 10 | B13: 37069 | C13: MIMANSHA | D13: Employee
A14: 11 | B14: 37068 | C14: NISHA MISHRA | D14: Employee
A15: 12 | B15: 37143 | C15: SANJANA KUMARI RAI | D15: Employee
... A24: 21 | B24: 37113 | C24: SHWETA YADAV | D24: Supply
